<?xml version='1.0' encoding='utf-8'?>
<robot name="test_robot">

  </link>
 <link name="link1" />
<mass value='1.0'/>
  </link>

  </link>
 <link name="link2" />
<mass value='1.0'/>
  </link>


 </link>
 <link name="link3" />
<mass value='1.0'/>
  </link>

 </link>
 <link name="link4" />
<mass value='1.0'/>
  </link>

<joint name="joint1" type="continuous">
 <parent link="link1"/>
 <child link="link2"/>
 <origin xyz="5 3 0" rpy="0 0 0" />
 <axis xyz="-0.9 0.15 0" />
</joint>

<joint name="joint2" type="continuous">
  <parent link="link1"/>
  <child link="link3"/>
  <origin xyz="-2 5 0" rpy="0 0 1.57" />
  <axis xyz="-0.707 0.707 0" />
</joint>

<joint name="joint3" type="continuous">
  <parent link="link3"/>
  <child link="link4"/>
  <origin xyz="5 0 0" rpy="0 0 -1.57" />
  <axis xyz="0.707 -0.707 0" />
</joint>
</robot>
