<?xml version="1.0" ?>
<robot name="iCubHeidelberg01_SIM_MODEL">
  <joint name="iCubHeidelberg01_SIM_MODEL__l_hip_pitch" type="revolute">
    <parent link="iCubHeidelberg01_SIM_MODEL__root_link"/>
    <child link="iCubHeidelberg01_SIM_MODEL__l_hip_1"/>
    <origin rpy="1.57159  0      -3.14159" xyz="-0.026    0.04273  0.54805"/>
    <axis xyz="1  0  0"/>
    <limit effort="50000.0" lower="-0.523599" upper="1.48353" velocity="50000.0"/>
  </joint>
  <joint name="iCubHeidelberg01_SIM_MODEL__l_hip_roll" type="revolute">
    <parent link="iCubHeidelberg01_SIM_MODEL__l_hip_1"/>
    <child link="iCubHeidelberg01_SIM_MODEL__l_hip_2"/>
    <origin rpy="0  0  0" xyz="-0.0961   0       0.02624"/>
    <axis xyz="0  0 -1"/>
    <limit effort="50000.0" lower="0.0" upper="1.5708" velocity="50000.0"/>
  </joint>
  <joint name="iCubHeidelberg01_SIM_MODEL__l_hip_yaw" type="revolute">
    <parent link="iCubHeidelberg01_SIM_MODEL__l_hip_2"/>
    <child link="iCubHeidelberg01_SIM_MODEL__l_thigh"/>
    <origin rpy="0  0  0" xyz="0      -0.0923  -0.02538"/>
    <axis xyz="0  1  0"/>
    <limit effort="50000.0" lower="-1.22173" upper="1.22173" velocity="50000.0"/>
  </joint>
  <joint name="iCubHeidelberg01_SIM_MODEL__l_knee" type="revolute">
    <parent link="iCubHeidelberg01_SIM_MODEL__l_thigh"/>
    <child link="iCubHeidelberg01_SIM_MODEL__l_shank"/>
    <origin rpy="0  0  0" xyz="-0.01788 -0.14562  0"/>
    <axis xyz="1  0  0"/>
    <limit effort="50000.0" lower="-1.74533" upper="0.0" velocity="50000.0"/>
  </joint>
  <joint name="iCubHeidelberg01_SIM_MODEL__l_ankle_pitch" type="revolute">
    <parent link="iCubHeidelberg01_SIM_MODEL__l_shank"/>
    <child link="iCubHeidelberg01_SIM_MODEL__l_ankle"/>
    <origin rpy="0  0  0" xyz="-0.01293 -0.2005   0"/>
    <axis xyz="-1  0  0"/>
    <limit effort="50000.0" lower="-0.349066" upper="0.523599" velocity="50000.0"/>
  </joint>
  <joint name="iCubHeidelberg01_SIM_MODEL__l_ankle_roll" type="revolute">
    <parent link="iCubHeidelberg01_SIM_MODEL__l_ankle"/>
    <child link="iCubHeidelberg01_SIM_MODEL__l_upper_foot"/>
    <origin rpy="0  0  0" xyz="0.02702  0      -0.04456"/>
    <axis xyz="0  0 -1"/>
    <limit effort="50000.0" lower="-0.349066" upper="0.349066" velocity="50000.0"/>
  </joint>
  <joint name="iCubHeidelberg01_SIM_MODEL__r_hip_pitch" type="revolute">
    <parent link="iCubHeidelberg01_SIM_MODEL__root_link"/>
    <child link="iCubHeidelberg01_SIM_MODEL__r_hip_1"/>
    <origin rpy="1.57  0    0" xyz="-0.02624  0.04273  0.54805"/>
    <axis xyz="-1  0  0"/>
    <limit effort="50000.0" lower="-0.523599" upper="1.48353" velocity="50000.0"/>
  </joint>
  <joint name="iCubHeidelberg01_SIM_MODEL__r_hip_roll" type="revolute">
    <parent link="iCubHeidelberg01_SIM_MODEL__r_hip_1"/>
    <child link="iCubHeidelberg01_SIM_MODEL__r_hip_2"/>
    <origin rpy="0  0  0" xyz="-0.04385  0      -0.02624"/>
    <axis xyz="0  0 -1"/>
    <limit effort="50000.0" lower="0.0" upper="1.5708" velocity="50000.0"/>
  </joint>
  <joint name="iCubHeidelberg01_SIM_MODEL__r_hip_yaw" type="revolute">
    <parent link="iCubHeidelberg01_SIM_MODEL__r_hip_2"/>
    <child link="iCubHeidelberg01_SIM_MODEL__r_thigh"/>
    <origin rpy="0  0  0" xyz="0      -0.0923   0.02539"/>
    <axis xyz="0 -1  0"/>
    <limit effort="50000.0" lower="-1.22173" upper="1.22173" velocity="50000.0"/>
  </joint>
  <joint name="iCubHeidelberg01_SIM_MODEL__r_knee" type="revolute">
    <parent link="iCubHeidelberg01_SIM_MODEL__r_thigh"/>
    <child link="iCubHeidelberg01_SIM_MODEL__r_shank"/>
    <origin rpy="0  0  0" xyz="-0.01789 -0.14562  0"/>
    <axis xyz="-1  0  0"/>
    <limit effort="50000.0" lower="-1.74533" upper="0.0" velocity="50000.0"/>
  </joint>
  <joint name="iCubHeidelberg01_SIM_MODEL__r_ankle_pitch" type="revolute">
    <parent link="iCubHeidelberg01_SIM_MODEL__r_shank"/>
    <child link="iCubHeidelberg01_SIM_MODEL__r_ankle"/>
    <origin rpy="0  0  0" xyz="-0.01293 -0.2005   0"/>
    <axis xyz="1  0  0"/>
    <limit effort="50000.0" lower="-0.349066" upper="0.523599" velocity="50000.0"/>
  </joint>
  <joint name="iCubHeidelberg01_SIM_MODEL__r_ankle_roll" type="revolute">
    <parent link="iCubHeidelberg01_SIM_MODEL__r_ankle"/>
    <child link="iCubHeidelberg01_SIM_MODEL__r_upper_foot"/>
    <origin rpy="0  0  0" xyz="0.02702  0       0.04456"/>
    <axis xyz="0  0 -1"/>
    <limit effort="50000.0" lower="-0.349066" upper="0.349066" velocity="50000.0"/>
  </joint>
  <joint name="iCubHeidelberg01_SIM_MODEL__torso_pitch" type="revolute">
    <parent link="iCubHeidelberg01_SIM_MODEL__root_link"/>
    <child link="iCubHeidelberg01_SIM_MODEL__lap_belt_1"/>
    <origin rpy="1.57  0    0" xyz="-0.03939  0.03637  0.66797"/>
    <axis xyz="1  0  0"/>
    <limit effort="50000.0" lower="-0.349066" upper="1.22173" velocity="50000.0"/>
  </joint>
  <joint name="iCubHeidelberg01_SIM_MODEL__torso_roll" type="revolute">
    <parent link="iCubHeidelberg01_SIM_MODEL__lap_belt_1"/>
    <child link="iCubHeidelberg01_SIM_MODEL__lap_belt_2"/>
    <origin rpy="0  0  0" xyz="0.03939  0.032   -0.05383"/>
    <axis xyz="0  0 -1"/>
    <limit effort="50000.0" lower="-0.523599" upper="0.523599" velocity="50000.0"/>
  </joint>
  <joint name="iCubHeidelberg01_SIM_MODEL__torso_yaw" type="revolute">
    <parent link="iCubHeidelberg01_SIM_MODEL__lap_belt_2"/>
    <child link="iCubHeidelberg01_SIM_MODEL__chest"/>
    <origin rpy="0  0  0" xyz="0       0.052    0.05933"/>
    <axis xyz="0 -1  0"/>
    <limit effort="50000.0" lower="-0.872665" upper="0.872665" velocity="50000.0"/>
  </joint>
  <link name="iCubHeidelberg01_SIM_MODEL__root_link">
    <inertial>
      <mass value="4.55132"/>
      <origin rpy="1.57  0    0" xyz="-1.70000000e-04   6.78400000e-02   6.17870000e-01"/>
      <inertia ixx="0.0133835" ixy="3.22057e-05" ixz="-6.77957e-05" iyy="0.0178931" iyz="-0.00175809" izz="0.020903"/>
    </inertial>
    <collision name="iCubHeidelberg01_SIM_MODEL__root_link_collision">
      <origin rpy="1.57  0    0" xyz="0   0   0.7"/>
      <geometry>
        <mesh filename="package://icub-gazebo/iCubHeidelberg01_model/dae_meshes/sim_sea_root_link_prt.dae" scale="0.001 0.001 0.001"/>
      </geometry>
    </collision>
    <visual name="iCubHeidelberg01_SIM_MODEL__root_link_visual">
      <origin rpy="1.57  0    0" xyz="0   0   0.7"/>
      <geometry>
        <mesh filename="package://icub-gazebo/iCubHeidelberg01_model/dae_meshes/sim_sea_root_link_prt.dae" scale="0.001 0.001 0.001"/>
      </geometry>
    </visual>
  </link>
  <link name="iCubHeidelberg01_SIM_MODEL__l_hip_1">
    <inertial>
      <mass value="0.610394"/>
      <origin rpy="0  0  0" xyz="-8.66600000e-02  -2.00000000e-05   2.10000000e-04"/>
      <inertia ixx="0.000304601" ixy="7.97583e-07" ixz="-2.29911e-07" iyy="0.000454222" iyz="1.14938e-06" izz="0.000453573"/>
    </inertial>
    <collision name="iCubHeidelberg01_SIM_MODEL__l_hip_1_collision">
      <origin rpy="0  0  0" xyz="-0.026    0.15191 -0.04285"/>
      <geometry>
        <mesh filename="package://icub-gazebo/iCubHeidelberg01_model/dae_meshes/sim_sea_l_hip_1_prt.dae" scale="0.001 0.001 0.001"/>
      </geometry>
    </collision>
    <visual name="iCubHeidelberg01_SIM_MODEL__l_hip_1_visual">
      <origin rpy="0  0  0" xyz="-0.026    0.15191 -0.04285"/>
      <geometry>
        <mesh filename="package://icub-gazebo/iCubHeidelberg01_model/dae_meshes/sim_sea_l_hip_1_prt.dae" scale="0.001 0.001 0.001"/>
      </geometry>
    </visual>
  </link>
  <link name="iCubHeidelberg01_SIM_MODEL__l_hip_2">
    <inertial>
      <mass value="0.415498"/>
      <origin rpy="0  0  0" xyz="5.00000000e-05  -5.02000000e-02  -2.37800000e-02"/>
      <inertia ixx="0.000623759" ixy="9.50818e-07" ixz="2.06495e-08" iyy="0.000287812" iyz="1.76173e-05" izz="0.000465225"/>
    </inertial>
    <collision name="iCubHeidelberg01_SIM_MODEL__l_hip_2_collision">
      <origin rpy="0  0  0" xyz="0.0701   0.15191 -0.06909"/>
      <geometry>
        <mesh filename="package://icub-gazebo/iCubHeidelberg01_model/dae_meshes/sim_sea_l_hip_2_prt.dae" scale="0.001 0.001 0.001"/>
      </geometry>
    </collision>
    <collision name="iCubHeidelberg01_SIM_MODEL__l_hip_2_collision_l_upper_thigh">
      <origin rpy="0  0  0" xyz="0.0701   0.15191 -0.06909"/>
      <geometry>
        <mesh filename="package://icub-gazebo/iCubHeidelberg01_model/dae_meshes/sim_sea_l_upper_thigh_prt.dae" scale="0.001 0.001 0.001"/>
      </geometry>
    </collision>
    <visual name="iCubHeidelberg01_SIM_MODEL__l_hip_2_visual">
      <origin rpy="0  0  0" xyz="0.0701   0.15191 -0.06909"/>
      <geometry>
        <mesh filename="package://icub-gazebo/iCubHeidelberg01_model/dae_meshes/sim_sea_l_hip_2_prt.dae" scale="0.001 0.001 0.001"/>
      </geometry>
    </visual>
    <visual name="iCubHeidelberg01_SIM_MODEL__l_hip_2_visual_l_upper_thigh">
      <origin rpy="0  0  0" xyz="0.0701   0.15191 -0.06909"/>
      <geometry>
        <mesh filename="package://icub-gazebo/iCubHeidelberg01_model/dae_meshes/sim_sea_l_upper_thigh_prt.dae" scale="0.001 0.001 0.001"/>
      </geometry>
    </visual>
  </link>
  <link name="iCubHeidelberg01_SIM_MODEL__l_thigh">
    <inertial>
      <mass value="2.82909"/>
      <origin rpy="0  0  0" xyz="-0.00014 -0.06508 -0.0091"/>
      <inertia ixx="0.00961828" ixy="0.000277522" ixz="7.45373e-06" iyy="0.00385108" iyz="-0.000180645" izz="0.00968964"/>
    </inertial>
    <collision name="iCubHeidelberg01_SIM_MODEL__l_thigh_collision">
      <origin rpy="0  0  0" xyz="0.0701   0.24101 -0.0437"/>
      <geometry>
        <mesh filename="package://icub-gazebo/iCubHeidelberg01_model/dae_meshes/sim_sea_l_thigh_prt.dae" scale="0.001 0.001 0.001"/>
      </geometry>
    </collision>
    <visual name="iCubHeidelberg01_SIM_MODEL__l_thigh_visual">
      <origin rpy="0  0  0" xyz="0.0701   0.24101 -0.0437"/>
      <geometry>
        <mesh filename="package://icub-gazebo/iCubHeidelberg01_model/dae_meshes/sim_sea_l_thigh_prt.dae" scale="0.001 0.001 0.001"/>
      </geometry>
    </visual>
  </link>
  <link name="iCubHeidelberg01_SIM_MODEL__l_shank">
    <inertial>
      <mass value="3.31111"/>
      <origin rpy="0  0  0" xyz="0.01207 -0.08302 -0.00735"/>
      <inertia ixx="0.0108069" ixy="0.000604622" ixz="5.98023e-06" iyy="0.00495004" iyz="-0.000693558" izz="0.0116311"/>
    </inertial>
    <collision name="iCubHeidelberg01_SIM_MODEL__l_shank_collision">
      <origin rpy="0  0  0" xyz="0.08418  0.38663 -0.0437"/>
      <geometry>
        <mesh filename="package://icub-gazebo/iCubHeidelberg01_model/dae_meshes/sim_sea_l_shank_prt.dae" scale="0.001 0.001 0.001"/>
      </geometry>
    </collision>
    <visual name="iCubHeidelberg01_SIM_MODEL__l_shank_visual">
      <origin rpy="0  0  0" xyz="0.08418  0.38663 -0.0437"/>
      <geometry>
        <mesh filename="package://icub-gazebo/iCubHeidelberg01_model/dae_meshes/sim_sea_l_shank_prt.dae" scale="0.001 0.001 0.001"/>
      </geometry>
    </visual>
  </link>
  <link name="iCubHeidelberg01_SIM_MODEL__l_ankle">
    <inertial>
      <mass value="0.554181"/>
      <origin rpy="0  0  0" xyz="2.65300000e-02   7.00000000e-05  -1.50100000e-02"/>
      <inertia ixx="0.000368295" ixy="2.92938e-07" ixz="-1.37313e-05" iyy="0.000414394" iyz="1.75709e-06" izz="0.00028171"/>
    </inertial>
    <collision name="iCubHeidelberg01_SIM_MODEL__l_ankle_collision">
      <origin rpy="0  0  0" xyz="0.09712  0.58713 -0.0437"/>
      <geometry>
        <mesh filename="package://icub-gazebo/iCubHeidelberg01_model/dae_meshes/sim_sea_l_ankle_prt.dae" scale="0.001 0.001 0.001"/>
      </geometry>
    </collision>
    <visual name="iCubHeidelberg01_SIM_MODEL__l_ankle_visual">
      <origin rpy="0  0  0" xyz="0.09712  0.58713 -0.0437"/>
      <geometry>
        <mesh filename="package://icub-gazebo/iCubHeidelberg01_model/dae_meshes/sim_sea_l_ankle_prt.dae" scale="0.001 0.001 0.001"/>
      </geometry>
    </visual>
  </link>
  <link name="iCubHeidelberg01_SIM_MODEL__l_upper_foot">
    <inertial>
      <mass value="1.13271"/>
      <origin rpy="0  0  0" xyz="-0.00409 -0.05626  0.01778"/>
      <inertia ixx="0.00363251" ixy="-2.49209e-05" ixz="-0.000169419" iyy="0.00388982" iyz="-0.000172016" izz="0.000959682"/>
    </inertial>
    <collision name="iCubHeidelberg01_SIM_MODEL__l_upper_foot_collision">
      <origin rpy="0  0  0" xyz="0.0701   0.58713  0.00085"/>
      <geometry>
        <mesh filename="package://icub-gazebo/iCubHeidelberg01_model/dae_meshes/sim_sea_l_foot_prt.dae" scale="0.001 0.001 0.001"/>
      </geometry>
    </collision>
    <collision name="iCubHeidelberg01_SIM_MODEL__l_upper_foot_collision_l_foot">
      <origin rpy="0  0  0" xyz="0.0701   0.58713  0.00085"/>
      <geometry>
        <mesh filename="package://icub-gazebo/iCubHeidelberg01_model/dae_meshes/sim_sea_l_sole_prt.dae" scale="0.001 0.001 0.001"/>
      </geometry>
    </collision>
    <visual name="iCubHeidelberg01_SIM_MODEL__l_upper_foot_visual">
      <origin rpy="0  0  0" xyz="0.0701   0.58713  0.00085"/>
      <geometry>
        <mesh filename="package://icub-gazebo/iCubHeidelberg01_model/dae_meshes/sim_sea_l_foot_prt.dae" scale="0.001 0.001 0.001"/>
      </geometry>
    </visual>
    <visual name="iCubHeidelberg01_SIM_MODEL__l_upper_foot_visual_l_foot">
      <origin rpy="0  0  0" xyz="0.0701   0.58713  0.00085"/>
      <geometry>
        <mesh filename="package://icub-gazebo/iCubHeidelberg01_model/dae_meshes/sim_sea_l_sole_prt.dae" scale="0.001 0.001 0.001"/>
      </geometry>
    </visual>
  </link>
  <link name="iCubHeidelberg01_SIM_MODEL__r_hip_1">
    <inertial>
      <mass value="0.610394"/>
      <origin rpy="0  0  0" xyz="-3.44200000e-02  -2.00000000e-05  -2.10000000e-04"/>
      <inertia ixx="0.000304601" ixy="7.97583e-07" ixz="-2.29911e-07" iyy="0.000454222" iyz="1.14938e-06" izz="0.000453573"/>
    </inertial>
    <collision name="iCubHeidelberg01_SIM_MODEL__r_hip_1_collision">
      <origin rpy="0  0  0" xyz="0.02624  0.15191  0.04285"/>
      <geometry>
        <mesh filename="package://icub-gazebo/iCubHeidelberg01_model/dae_meshes/sim_sea_r_hip_1_prt.dae" scale="0.001 0.001 0.001"/>
      </geometry>
    </collision>
    <visual name="iCubHeidelberg01_SIM_MODEL__r_hip_1_visual">
      <origin rpy="0  0  0" xyz="0.02624  0.15191  0.04285"/>
      <geometry>
        <mesh filename="package://icub-gazebo/iCubHeidelberg01_model/dae_meshes/sim_sea_r_hip_1_prt.dae" scale="0.001 0.001 0.001"/>
      </geometry>
    </visual>
  </link>
  <link name="iCubHeidelberg01_SIM_MODEL__r_hip_2">
    <inertial>
      <mass value="0.415498"/>
      <origin rpy="0  0  0" xyz="5.00000000e-05  -5.02000000e-02   2.37800000e-02"/>
      <inertia ixx="0.000623759" ixy="9.50818e-07" ixz="-4.66603e-08" iyy="0.000287812" iyz="3.44947e-05" izz="0.000465225"/>
    </inertial>
    <collision name="iCubHeidelberg01_SIM_MODEL__r_hip_2_collision">
      <origin rpy="0  0  0" xyz="0.0701   0.15191  0.06909"/>
      <geometry>
        <mesh filename="package://icub-gazebo/iCubHeidelberg01_model/dae_meshes/sim_sea_r_hip_2_prt.dae" scale="0.001 0.001 0.001"/>
      </geometry>
    </collision>
    <collision name="iCubHeidelberg01_SIM_MODEL__r_hip_2_collision_r_upper_thigh">
      <origin rpy="0  0  0" xyz="0.0701   0.15191  0.06909"/>
      <geometry>
        <mesh filename="package://icub-gazebo/iCubHeidelberg01_model/dae_meshes/sim_sea_r_upper_thigh_prt.dae" scale="0.001 0.001 0.001"/>
      </geometry>
    </collision>
    <visual name="iCubHeidelberg01_SIM_MODEL__r_hip_2_visual">
      <origin rpy="0  0  0" xyz="0.0701   0.15191  0.06909"/>
      <geometry>
        <mesh filename="package://icub-gazebo/iCubHeidelberg01_model/dae_meshes/sim_sea_r_hip_2_prt.dae" scale="0.001 0.001 0.001"/>
      </geometry>
    </visual>
    <visual name="iCubHeidelberg01_SIM_MODEL__r_hip_2_visual_r_upper_thigh">
      <origin rpy="0  0  0" xyz="0.0701   0.15191  0.06909"/>
      <geometry>
        <mesh filename="package://icub-gazebo/iCubHeidelberg01_model/dae_meshes/sim_sea_r_upper_thigh_prt.dae" scale="0.001 0.001 0.001"/>
      </geometry>
    </visual>
  </link>
  <link name="iCubHeidelberg01_SIM_MODEL__r_thigh">
    <inertial>
      <mass value="2.82909"/>
      <origin rpy="0  0  0" xyz="-0.00014 -0.06508  0.0091"/>
      <inertia ixx="0.00961828" ixy="0.000277522" ixz="7.45373e-06" iyy="0.00385108" iyz="-0.000180645" izz="0.00968964"/>
    </inertial>
    <collision name="iCubHeidelberg01_SIM_MODEL__r_thigh_collision">
      <origin rpy="0  0  0" xyz="0.0701   0.24101  0.0437"/>
      <geometry>
        <mesh filename="package://icub-gazebo/iCubHeidelberg01_model/dae_meshes/sim_sea_r_thigh_prt.dae" scale="0.001 0.001 0.001"/>
      </geometry>
    </collision>
    <visual name="iCubHeidelberg01_SIM_MODEL__r_thigh_visual">
      <origin rpy="0  0  0" xyz="0.0701   0.24101  0.0437"/>
      <geometry>
        <mesh filename="package://icub-gazebo/iCubHeidelberg01_model/dae_meshes/sim_sea_r_thigh_prt.dae" scale="0.001 0.001 0.001"/>
      </geometry>
    </visual>
  </link>
  <link name="iCubHeidelberg01_SIM_MODEL__r_shank">
    <inertial>
      <mass value="3.31111"/>
      <origin rpy="0  0  0" xyz="0.01207 -0.08302  0.00735"/>
      <inertia ixx="0.0108069" ixy="0.000604622" ixz="5.98023e-06" iyy="0.00495004" iyz="-0.000693558" izz="0.0116311"/>
    </inertial>
    <collision name="iCubHeidelberg01_SIM_MODEL__r_shank_collision">
      <origin rpy="0  0  0" xyz="0.08419  0.38663  0.0437"/>
      <geometry>
        <mesh filename="package://icub-gazebo/iCubHeidelberg01_model/dae_meshes/sim_sea_r_shank_prt.dae" scale="0.001 0.001 0.001"/>
      </geometry>
    </collision>
    <visual name="iCubHeidelberg01_SIM_MODEL__r_shank_visual">
      <origin rpy="0  0  0" xyz="0.08419  0.38663  0.0437"/>
      <geometry>
        <mesh filename="package://icub-gazebo/iCubHeidelberg01_model/dae_meshes/sim_sea_r_shank_prt.dae" scale="0.001 0.001 0.001"/>
      </geometry>
    </visual>
  </link>
  <link name="iCubHeidelberg01_SIM_MODEL__r_ankle">
    <inertial>
      <mass value="0.554181"/>
      <origin rpy="0  0  0" xyz="2.65300000e-02   7.00000000e-05   1.50100000e-02"/>
      <inertia ixx="0.000368295" ixy="2.92938e-07" ixz="-1.37313e-05" iyy="0.000414394" iyz="1.75709e-06" izz="0.00028171"/>
    </inertial>
    <collision name="iCubHeidelberg01_SIM_MODEL__r_ankle_collision">
      <origin rpy="0  0  0" xyz="0.09712  0.58713  0.0437"/>
      <geometry>
        <mesh filename="package://icub-gazebo/iCubHeidelberg01_model/dae_meshes/sim_sea_r_ankle_prt.dae" scale="0.001 0.001 0.001"/>
      </geometry>
    </collision>
    <visual name="iCubHeidelberg01_SIM_MODEL__r_ankle_visual">
      <origin rpy="0  0  0" xyz="0.09712  0.58713  0.0437"/>
      <geometry>
        <mesh filename="package://icub-gazebo/iCubHeidelberg01_model/dae_meshes/sim_sea_r_ankle_prt.dae" scale="0.001 0.001 0.001"/>
      </geometry>
    </visual>
  </link>
  <link name="iCubHeidelberg01_SIM_MODEL__r_upper_foot">
    <inertial>
      <mass value="1.13271"/>
      <origin rpy="0  0  0" xyz="-0.00409 -0.05626 -0.01778"/>
      <inertia ixx="0.00363251" ixy="-2.49209e-05" ixz="-0.000108248" iyy="0.00388982" iyz="0.00016324" izz="0.000959682"/>
    </inertial>
    <collision name="iCubHeidelberg01_SIM_MODEL__r_upper_foot_collision">
      <origin rpy="0  0  0" xyz="0.0701   0.58713 -0.00085"/>
      <geometry>
        <mesh filename="package://icub-gazebo/iCubHeidelberg01_model/dae_meshes/sim_sea_r_foot_prt.dae" scale="0.001 0.001 0.001"/>
      </geometry>
    </collision>
    <collision name="iCubHeidelberg01_SIM_MODEL__r_upper_foot_collision_r_foot">
      <origin rpy="0  0  0" xyz="0.0701   0.58713 -0.00085"/>
      <geometry>
        <mesh filename="package://icub-gazebo/iCubHeidelberg01_model/dae_meshes/sim_sea_r_sole_prt.dae" scale="0.001 0.001 0.001"/>
      </geometry>
    </collision>
    <visual name="iCubHeidelberg01_SIM_MODEL__r_upper_foot_visual">
      <origin rpy="0  0  0" xyz="0.0701   0.58713 -0.00085"/>
      <geometry>
        <mesh filename="package://icub-gazebo/iCubHeidelberg01_model/dae_meshes/sim_sea_r_foot_prt.dae" scale="0.001 0.001 0.001"/>
      </geometry>
    </visual>
    <visual name="iCubHeidelberg01_SIM_MODEL__r_upper_foot_visual_r_foot">
      <origin rpy="0  0  0" xyz="0.0701   0.58713 -0.00085"/>
      <geometry>
        <mesh filename="package://icub-gazebo/iCubHeidelberg01_model/dae_meshes/sim_sea_r_sole_prt.dae" scale="0.001 0.001 0.001"/>
      </geometry>
    </visual>
  </link>
  <link name="iCubHeidelberg01_SIM_MODEL__lap_belt_1">
    <inertial>
      <mass value="0.479404"/>
      <origin rpy="0  0  0" xyz="0.03924  0.02811 -0.00332"/>
      <inertia ixx="0.000332949" ixy="-2.39782e-06" ixz="3.60866e-07" iyy="0.000309732" iyz="1.13592e-05" izz="0.000223739"/>
    </inertial>
    <collision name="iCubHeidelberg01_SIM_MODEL__lap_belt_1_collision">
      <origin rpy="0  0  0" xyz="0.03939  0.032    0.0364"/>
      <geometry>
        <mesh filename="package://icub-gazebo/iCubHeidelberg01_model/dae_meshes/sim_sea_lap_belt_1_prt.dae" scale="0.001 0.001 0.001"/>
      </geometry>
    </collision>
    <visual name="iCubHeidelberg01_SIM_MODEL__lap_belt_1_visual">
      <origin rpy="0  0  0" xyz="0.03939  0.032    0.0364"/>
      <geometry>
        <mesh filename="package://icub-gazebo/iCubHeidelberg01_model/dae_meshes/sim_sea_lap_belt_1_prt.dae" scale="0.001 0.001 0.001"/>
      </geometry>
    </visual>
  </link>
  <link name="iCubHeidelberg01_SIM_MODEL__lap_belt_2">
    <inertial>
      <mass value="0.327897"/>
      <origin rpy="0  0  0" xyz="-0.0001   0.02479  0.05352"/>
      <inertia ixx="0.000531991" ixy="5.54439e-07" ixz="-2.83073e-07" iyy="0.00042219" iyz="2.9326e-05" izz="0.000303736"/>
    </inertial>
    <collision name="iCubHeidelberg01_SIM_MODEL__lap_belt_2_collision">
      <origin rpy="0  0  0" xyz="0       0       0.09023"/>
      <geometry>
        <mesh filename="package://icub-gazebo/iCubHeidelberg01_model/dae_meshes/sim_kor_lap_belt_2_prt.dae" scale="0.001 0.001 0.001"/>
      </geometry>
    </collision>
    <visual name="iCubHeidelberg01_SIM_MODEL__lap_belt_2_visual">
      <origin rpy="0  0  0" xyz="0       0       0.09023"/>
      <geometry>
        <mesh filename="package://icub-gazebo/iCubHeidelberg01_model/dae_meshes/sim_kor_lap_belt_2_prt.dae" scale="0.001 0.001 0.001"/>
      </geometry>
    </visual>
  </link>
  <link name="iCubHeidelberg01_SIM_MODEL__chest">
    <inertial>
      <mass value="15.7261"/>
      <origin rpy="0  0  0" xyz="-0.00039  0.11046 -0.00764"/>
      <inertia ixx="0.0859471" ixy="-0.000159228" ixz="-0.000144573" iyy="0.15267" iyz="0.000717878" izz="0.175503"/>
    </inertial>
    <collision name="iCubHeidelberg01_SIM_MODEL__chest_collision">
      <origin rpy="0  0  0" xyz="0     -0.052   0.0309"/>
      <geometry>
        <mesh filename="package://icub-gazebo/iCubHeidelberg01_model/dae_meshes/sim_kor_chest_prt.dae" scale="0.001 0.001 0.001"/>
      </geometry>
    </collision>
    <collision name="iCubHeidelberg01_SIM_MODEL__chest_collision_WEIGHT-1KG">
      <origin rpy="1.5708  0     -1.5708" xyz="0.13225  0.0955   0"/>
      <geometry>
        <mesh filename="package://icub-gazebo/iCubHeidelberg01_model/dae_meshes/weight-1kg_prt.dae" scale="0.001 0.001 0.001"/>
      </geometry>
    </collision>
    <collision name="iCubHeidelberg01_SIM_MODEL__chest_collision_WEIGHT-1KG-1">
      <origin rpy="1.5708  0     -1.5708" xyz="0.15075  0.0955   0"/>
      <geometry>
        <mesh filename="package://icub-gazebo/iCubHeidelberg01_model/dae_meshes/weight-1kg_prt.dae" scale="0.001 0.001 0.001"/>
      </geometry>
    </collision>
    <collision name="iCubHeidelberg01_SIM_MODEL__chest_collision_WEIGHT-1KG-2">
      <origin rpy="1.5708  0      0" xyz="0       0.20675  0"/>
      <geometry>
        <mesh filename="package://icub-gazebo/iCubHeidelberg01_model/dae_meshes/weight-1kg_prt.dae" scale="0.001 0.001 0.001"/>
      </geometry>
    </collision>
    <collision name="iCubHeidelberg01_SIM_MODEL__chest_collision_WEIGHT-1KG-3">
      <origin rpy="1.5708  0      0" xyz="0       0.22525  0"/>
      <geometry>
        <mesh filename="package://icub-gazebo/iCubHeidelberg01_model/dae_meshes/weight-1kg_prt.dae" scale="0.001 0.001 0.001"/>
      </geometry>
    </collision>
    <collision name="iCubHeidelberg01_SIM_MODEL__chest_collision_WEIGHT-1KG-4">
      <origin rpy="1.5708  0      1.5708" xyz="-0.13225  0.0955   0"/>
      <geometry>
        <mesh filename="package://icub-gazebo/iCubHeidelberg01_model/dae_meshes/weight-1kg_prt.dae" scale="0.001 0.001 0.001"/>
      </geometry>
    </collision>
    <collision name="iCubHeidelberg01_SIM_MODEL__chest_collision_WEIGHT-1KG-5">
      <origin rpy="1.5708  0      1.5708" xyz="-0.15075  0.0955   0"/>
      <geometry>
        <mesh filename="package://icub-gazebo/iCubHeidelberg01_model/dae_meshes/weight-1kg_prt.dae" scale="0.001 0.001 0.001"/>
      </geometry>
    </collision>
    <visual name="iCubHeidelberg01_SIM_MODEL__chest_visual">
      <origin rpy="0  0  0" xyz="0     -0.052   0.0309"/>
      <geometry>
        <mesh filename="package://icub-gazebo/iCubHeidelberg01_model/dae_meshes/sim_kor_chest_prt.dae" scale="0.001 0.001 0.001"/>
      </geometry>
    </visual>
    <visual name="iCubHeidelberg01_SIM_MODEL__chest_visual_WEIGHT-1KG">
      <origin rpy="1.5708  0     -1.5708" xyz="0.13225  0.0955   0"/>
      <geometry>
        <mesh filename="package://icub-gazebo/iCubHeidelberg01_model/dae_meshes/weight-1kg_prt.dae" scale="0.001 0.001 0.001"/>
      </geometry>
    </visual>
    <visual name="iCubHeidelberg01_SIM_MODEL__chest_visual_WEIGHT-1KG-1">
      <origin rpy="1.5708  0     -1.5708" xyz="0.15075  0.0955   0"/>
      <geometry>
        <mesh filename="package://icub-gazebo/iCubHeidelberg01_model/dae_meshes/weight-1kg_prt.dae" scale="0.001 0.001 0.001"/>
      </geometry>
    </visual>
    <visual name="iCubHeidelberg01_SIM_MODEL__chest_visual_WEIGHT-1KG-2">
      <origin rpy="1.5708  0      0" xyz="0       0.20675  0"/>
      <geometry>
        <mesh filename="package://icub-gazebo/iCubHeidelberg01_model/dae_meshes/weight-1kg_prt.dae" scale="0.001 0.001 0.001"/>
      </geometry>
    </visual>
    <visual name="iCubHeidelberg01_SIM_MODEL__chest_visual_WEIGHT-1KG-3">
      <origin rpy="1.5708  0      0" xyz="0       0.22525  0"/>
      <geometry>
        <mesh filename="package://icub-gazebo/iCubHeidelberg01_model/dae_meshes/weight-1kg_prt.dae" scale="0.001 0.001 0.001"/>
      </geometry>
    </visual>
    <visual name="iCubHeidelberg01_SIM_MODEL__chest_visual_WEIGHT-1KG-4">
      <origin rpy="1.5708  0      1.5708" xyz="-0.13225  0.0955   0"/>
      <geometry>
        <mesh filename="package://icub-gazebo/iCubHeidelberg01_model/dae_meshes/weight-1kg_prt.dae" scale="0.001 0.001 0.001"/>
      </geometry>
    </visual>
    <visual name="iCubHeidelberg01_SIM_MODEL__chest_visual_WEIGHT-1KG-5">
      <origin rpy="1.5708  0      1.5708" xyz="-0.15075  0.0955   0"/>
      <geometry>
        <mesh filename="package://icub-gazebo/iCubHeidelberg01_model/dae_meshes/weight-1kg_prt.dae" scale="0.001 0.001 0.001"/>
      </geometry>
    </visual>
  </link>
</robot>
